pydev debugger: process 24829 is connecting

Traceback (most recent call last):
  File "/Applications/PyCharm CE.app/Contents/helpers/pydev/pydevd.py", line 1668, in <module>
    main()
  File "/Applications/PyCharm CE.app/Contents/helpers/pydev/pydevd.py", line 1662, in main
    globals = debugger.run(setup['file'], None, None, is_module)
  File "/Applications/PyCharm CE.app/Contents/helpers/pydev/pydevd.py", line 1072, in run
    pydev_imports.execfile(file, globals, locals)  # execute the script
  File "/Applications/PyCharm CE.app/Contents/helpers/pydev/_pydev_imps/_pydev_execfile.py", line 11, in execfile
    stream = tokenize.open(file)  # @UndefinedVariable
  File "/Users/amit/anaconda2/envs/myenv/lib/python3.6/tokenize.py", line 452, in open
    buffer = _builtin_open(filename, 'rb')
FileNotFoundError: [Errno 2] No such file or directory: '/Users/amit/Desktop/Dropbox/Python/blobs/blob_detector_a.py'
